<?xml version="1.0"?>
<robot xmlns:xacro="http://www.ros.org/wiki/xacro" >

    <xacro:include filename="quan_tinh.xacro"/>
    <material name="trang">
        <color rgba="1 1 1 1"/>
    </material>

    <material name="xanhduong">
        <color rgba="0 0 1 1"/>
    </material>

    <material name="vang">
        <color rgba="1 1 0 1"/>
    </material>

    <material name="do">
        <color rgba="1 0 0 1"/>
    </material>

    <material name="vangdam">
        <color rgba="1 0.8 0 1"/>
    </material>

    <material name="xanhla">
        <color rgba="0 1 0 1"/>
    </material>

    <material name="den">
        <color rgba="0 0 0 0"/>
    </material>

    <!-- BASE LINK -->
    <link name="base_link"/>

`   <!-- BASE_FOOTPRINT LINK -->
    <joint name="base_footprint_joint" type="fixed">
        <parent link="base_link"/>
        <child link="base_footprint"/>
        <origin xyz="0 0 0" rpy="0 0 0"/>
    </joint>

    <link name="base_footprint">
    </link>
    
    <!-- khung link -->
    <joint name="khop_khung" type="fixed">
        <parent link="base_link"/>
        <child link="khung"/>
        <origin xyz="-0.03 0 0"/>
    </joint>

    <link name="khung">
        <visual>
            <origin xyz="0.1 0 0.028"/>
            <geometry>
                <box size="0.2 0.12 0.04"/>
            </geometry>
            <material name="vangdam"/>
        </visual>

        <collision>
            <origin xyz="0.1 0 0.028"/>
            <geometry>
                <box size="0.2 0.12 0.04"/>
            </geometry>
            <material name="vangdam"/>
        </collision>
        
        <xacro:quan_tinh_hop mass="0.5" x="0.2" y="0.12" z="0.05">
            <origin xyz="0.1 0 0.028" rpy="0 0 0"/>
        </xacro:quan_tinh_hop>
    </link>

    <!-- Bánh trái -->
    <joint name="khop_banh_trai" type="continuous">
        <parent link="base_link"/>
        <child link="banh_trai"/>
        <origin xyz="0 0.09 0" rpy="-1.5708 0 0"/>
        <axis xyz="0 0 1"/>
    </joint>

    <link name="banh_trai">
        <visual>
            <geometry>
                <cylinder radius="0.0275" length="0.042"/>
            </geometry>
            <material name="den"/>
        </visual>

        <collision>
            <geometry>
                <cylinder radius="0.0275" length="0.042"/>
            </geometry>
        </collision>

        <xacro:quan_tinh_tru mass="0.05" length="0.042" radius="0.0275">
            <origin xyz="0 0 0" rpy="0 0 0"/>
        </xacro:quan_tinh_tru>
    </link> 

    <!-- Bánh phải -->
    <joint name="khop_banh_phai" type="continuous">
        <parent link="base_link"/>
        <child link="banh_phai"/>
        <origin xyz="0 -0.09 0" rpy="1.5708 0 0"/>
        <axis xyz="0 0 -1"/>
    </joint>

    <link name="banh_phai">
        <visual>
            <geometry>
                <cylinder radius="0.0275" length="0.042"/>
            </geometry>
            <material name="den"/>
        </visual>

        <collision>
            <geometry>
                <cylinder radius="0.0275" length="0.042"/>
            </geometry>
        </collision>

        <xacro:quan_tinh_tru mass="0.05" length="0.042" radius="0.0275">
            <origin xyz="0 0 0" rpy="0 0 0"/>
        </xacro:quan_tinh_tru>
    </link> 

        <!-- Bánh trái 1 -->
    <joint name="khop_banh_trai_1" type="fixed">
        <parent link="base_link"/>
        <child link="banh_trai_1"/>
        <origin xyz="0.07 0.09 0" rpy="-1.5708 0 0"/>
        <axis xyz="0 0 1"/>
    </joint>

    <link name="banh_trai_1">
        <visual>
            <geometry>
                <cylinder radius="0.0275" length="0.042"/>
            </geometry>
            <material name="xanhduong"/>
        </visual>

        <collision>
            <geometry>
                <cylinder radius="0.0275" length="0.042"/>
            </geometry>
        </collision>

        <xacro:quan_tinh_tru mass="0.05" length="0.042" radius="0.0275">
            <origin xyz="0 0 0" rpy="0 0 0"/>
        </xacro:quan_tinh_tru>
    </link> 

    <gazebo reference="banh_trai_1">
        <material>Gazebo/Black</material>
        <mu1 value="0.01"/>
        <mu2 value="0.01"/>
    </gazebo>

    <!-- Bánh phải 1 -->
    <joint name="khop_banh_phai_1" type="fixed">
        <parent link="base_link"/>
        <child link="banh_phai_1"/>
        <origin xyz="0.07 -0.09 0" rpy="1.5708 0 0"/>
        <axis xyz="0 0 -1"/>
    </joint>

    <link name="banh_phai_1">
        <visual>
            <geometry>
                <cylinder radius="0.0275" length="0.042"/>
            </geometry>
            <material name="xanhduong"/>
        </visual>

        <collision>
            <geometry>
                <cylinder radius="0.0275" length="0.042"/>
            </geometry>
        </collision>

        <xacro:quan_tinh_tru mass="0.05" length="0.042" radius="0.0275">
            <origin xyz="0 0 0" rpy="0 0 0"/>
        </xacro:quan_tinh_tru>
    </link> 

    <gazebo reference="banh_phai_1">
        <material>Gazebo/Black</material>
        <mu1 value="0.01"/>
        <mu2 value="0.01"/>
    </gazebo>

        <!-- Bánh trái 2-->
    <joint name="khop_banh_trai_2" type="fixed">
        <parent link="base_link"/>
        <child link="banh_trai_2"/>
        <origin xyz="0.135 0.09 0" rpy="-1.5708 0 0"/>
        <axis xyz="0 0 1"/>
    </joint>

    <link name="banh_trai_2">
        <visual>
            <geometry>
                <cylinder radius="0.0275" length="0.042"/>
            </geometry>
            <material name="xanhduong"/>
        </visual>

        <collision>
            <geometry>
                <cylinder radius="0.0275" length="0.042"/>
            </geometry>
        </collision>

        <xacro:quan_tinh_tru mass="0.05" length="0.042" radius="0.0275">
            <origin xyz="0 0 0" rpy="0 0 0"/>
        </xacro:quan_tinh_tru>
    </link> 
    
    <gazebo reference="banh_trai_2">
        <material>Gazebo/Black</material>
        <mu1 value="0.01"/>
        <mu2 value="0.01"/>
    </gazebo>

    <!-- Bánh phải 2-->
    <joint name="khop_banh_phai_2" type="fixed">
        <parent link="base_link"/>
        <child link="banh_phai_2"/>
        <origin xyz="0.135 -0.09 0" rpy="1.5708 0 0"/>
        <axis xyz="0 0 -1"/>
    </joint>

    <link name="banh_phai_2">
        <visual>
            <geometry>
                <cylinder radius="0.0275" length="0.042"/>
            </geometry>
            <material name="xanhduong"/>
        </visual>

        <collision>
            <geometry>
                <cylinder radius="0.0275" length="0.042"/>
            </geometry>
        </collision>

        <xacro:quan_tinh_tru mass="0.05" length="0.042" radius="0.0275">
            <origin xyz="0 0 0" rpy="0 0 0"/>
        </xacro:quan_tinh_tru>
    </link> 

    <gazebo reference="banh_phai_2">
        <material>Gazebo/Black</material>
        <mu1 value="0.01"/>
        <mu2 value="0.01"/>
    </gazebo>

</robot>
